[W socket.cpp:436] [c10d] The server socket has failed to bind to [::]:29501 (errno: 98 - Address already in use).
[W socket.cpp:436] [c10d] The server socket has failed to bind to 0.0.0.0:29501 (errno: 98 - Address already in use).
[E socket.cpp:472] [c10d] The server socket has failed to listen on any local network address.
Process Process-1:
Traceback (most recent call last):
  File "/home/jroth/.conda/envs/mct/lib/python3.10/multiprocessing/process.py", line 314, in _bootstrap
    self.run()
  File "/home/jroth/.conda/envs/mct/lib/python3.10/multiprocessing/process.py", line 108, in run
    self._target(*self._args, **self._kwargs)
  File "/home/luketerry/distributed_dino_embedding/distributed_process.py", line 66, in init_process
    dist.init_process_group(backend, rank=rank, world_size=size)
  File "/home/jroth/.conda/envs/mct/lib/python3.10/site-packages/torch/distributed/c10d_logger.py", line 74, in wrapper
    func_return = func(*args, **kwargs)
  File "/home/jroth/.conda/envs/mct/lib/python3.10/site-packages/torch/distributed/distributed_c10d.py", line 1141, in init_process_group
    store, rank, world_size = next(rendezvous_iterator)
  File "/home/jroth/.conda/envs/mct/lib/python3.10/site-packages/torch/distributed/rendezvous.py", line 241, in _env_rendezvous_handler
    store = _create_c10d_store(master_addr, master_port, rank, world_size, timeout)
  File "/home/jroth/.conda/envs/mct/lib/python3.10/site-packages/torch/distributed/rendezvous.py", line 172, in _create_c10d_store
    return TCPStore(
RuntimeError: The server socket has failed to listen on any local network address. The server socket has failed to bind to [::]:29501 (errno: 98 - Address already in use). The server socket has failed to bind to 0.0.0.0:29501 (errno: 98 - Address already in use).
[W socket.cpp:436] [c10d] The server socket has failed to bind to [::]:29501 (errno: 98 - Address already in use).
[W socket.cpp:436] [c10d] The server socket has failed to bind to 0.0.0.0:29501 (errno: 98 - Address already in use).
[E socket.cpp:472] [c10d] The server socket has failed to listen on any local network address.
Process Process-1:
Traceback (most recent call last):
  File "/home/jroth/.conda/envs/mct/lib/python3.10/multiprocessing/process.py", line 314, in _bootstrap
    self.run()
  File "/home/jroth/.conda/envs/mct/lib/python3.10/multiprocessing/process.py", line 108, in run
    self._target(*self._args, **self._kwargs)
  File "/home/luketerry/distributed_dino_embedding/distributed_process.py", line 66, in init_process
    dist.init_process_group(backend, rank=rank, world_size=size)
  File "/home/jroth/.conda/envs/mct/lib/python3.10/site-packages/torch/distributed/c10d_logger.py", line 74, in wrapper
    func_return = func(*args, **kwargs)
  File "/home/jroth/.conda/envs/mct/lib/python3.10/site-packages/torch/distributed/distributed_c10d.py", line 1141, in init_process_group
    store, rank, world_size = next(rendezvous_iterator)
  File "/home/jroth/.conda/envs/mct/lib/python3.10/site-packages/torch/distributed/rendezvous.py", line 241, in _env_rendezvous_handler
    store = _create_c10d_store(master_addr, master_port, rank, world_size, timeout)
  File "/home/jroth/.conda/envs/mct/lib/python3.10/site-packages/torch/distributed/rendezvous.py", line 172, in _create_c10d_store
    return TCPStore(
RuntimeError: The server socket has failed to listen on any local network address. The server socket has failed to bind to [::]:29501 (errno: 98 - Address already in use). The server socket has failed to bind to 0.0.0.0:29501 (errno: 98 - Address already in use).
[W socket.cpp:436] [c10d] The server socket has failed to bind to [::]:29501 (errno: 98 - Address already in use).
[W socket.cpp:436] [c10d] The server socket has failed to bind to 0.0.0.0:29501 (errno: 98 - Address already in use).
[E socket.cpp:472] [c10d] The server socket has failed to listen on any local network address.
Process Process-1:
Traceback (most recent call last):
  File "/home/jroth/.conda/envs/mct/lib/python3.10/multiprocessing/process.py", line 314, in _bootstrap
    self.run()
  File "/home/jroth/.conda/envs/mct/lib/python3.10/multiprocessing/process.py", line 108, in run
    self._target(*self._args, **self._kwargs)
  File "/home/luketerry/distributed_dino_embedding/distributed_process.py", line 66, in init_process
    dist.init_process_group(backend, rank=rank, world_size=size)
  File "/home/jroth/.conda/envs/mct/lib/python3.10/site-packages/torch/distributed/c10d_logger.py", line 74, in wrapper
    func_return = func(*args, **kwargs)
  File "/home/jroth/.conda/envs/mct/lib/python3.10/site-packages/torch/distributed/distributed_c10d.py", line 1141, in init_process_group
    store, rank, world_size = next(rendezvous_iterator)
  File "/home/jroth/.conda/envs/mct/lib/python3.10/site-packages/torch/distributed/rendezvous.py", line 241, in _env_rendezvous_handler
    store = _create_c10d_store(master_addr, master_port, rank, world_size, timeout)
  File "/home/jroth/.conda/envs/mct/lib/python3.10/site-packages/torch/distributed/rendezvous.py", line 172, in _create_c10d_store
    return TCPStore(
RuntimeError: The server socket has failed to listen on any local network address. The server socket has failed to bind to [::]:29501 (errno: 98 - Address already in use). The server socket has failed to bind to 0.0.0.0:29501 (errno: 98 - Address already in use).
/home/luketerry/.cache/torch/hub/facebookresearch_dinov2_main/dinov2/layers/swiglu_ffn.py:51: UserWarning: xFormers is not available (SwiGLU)
  warnings.warn("xFormers is not available (SwiGLU)")
/home/luketerry/.cache/torch/hub/facebookresearch_dinov2_main/dinov2/layers/attention.py:33: UserWarning: xFormers is not available (Attention)
  warnings.warn("xFormers is not available (Attention)")
/home/luketerry/.cache/torch/hub/facebookresearch_dinov2_main/dinov2/layers/block.py:40: UserWarning: xFormers is not available (Block)
  warnings.warn("xFormers is not available (Block)")
/home/luketerry/.cache/torch/hub/facebookresearch_dinov2_main/dinov2/layers/swiglu_ffn.py:51: UserWarning: xFormers is not available (SwiGLU)
  warnings.warn("xFormers is not available (SwiGLU)")
/home/luketerry/.cache/torch/hub/facebookresearch_dinov2_main/dinov2/layers/swiglu_ffn.py:51: UserWarning: xFormers is not available (SwiGLU)
  warnings.warn("xFormers is not available (SwiGLU)")
/home/luketerry/.cache/torch/hub/facebookresearch_dinov2_main/dinov2/layers/attention.py:33: UserWarning: xFormers is not available (Attention)
  warnings.warn("xFormers is not available (Attention)")
/home/luketerry/.cache/torch/hub/facebookresearch_dinov2_main/dinov2/layers/attention.py:33: UserWarning: xFormers is not available (Attention)
  warnings.warn("xFormers is not available (Attention)")
/home/luketerry/.cache/torch/hub/facebookresearch_dinov2_main/dinov2/layers/block.py:40: UserWarning: xFormers is not available (Block)
  warnings.warn("xFormers is not available (Block)")
/home/luketerry/.cache/torch/hub/facebookresearch_dinov2_main/dinov2/layers/block.py:40: UserWarning: xFormers is not available (Block)
  warnings.warn("xFormers is not available (Block)")
/home/luketerry/.cache/torch/hub/facebookresearch_dinov2_main/dinov2/layers/swiglu_ffn.py:51: UserWarning: xFormers is not available (SwiGLU)
  warnings.warn("xFormers is not available (SwiGLU)")
/home/luketerry/.cache/torch/hub/facebookresearch_dinov2_main/dinov2/layers/attention.py:33: UserWarning: xFormers is not available (Attention)
  warnings.warn("xFormers is not available (Attention)")
/home/luketerry/.cache/torch/hub/facebookresearch_dinov2_main/dinov2/layers/block.py:40: UserWarning: xFormers is not available (Block)
  warnings.warn("xFormers is not available (Block)")
/home/luketerry/.cache/torch/hub/facebookresearch_dinov2_main/dinov2/layers/swiglu_ffn.py:51: UserWarning: xFormers is not available (SwiGLU)
  warnings.warn("xFormers is not available (SwiGLU)")
/home/luketerry/.cache/torch/hub/facebookresearch_dinov2_main/dinov2/layers/attention.py:33: UserWarning: xFormers is not available (Attention)
  warnings.warn("xFormers is not available (Attention)")
/home/luketerry/.cache/torch/hub/facebookresearch_dinov2_main/dinov2/layers/block.py:40: UserWarning: xFormers is not available (Block)
  warnings.warn("xFormers is not available (Block)")
/home/luketerry/.cache/torch/hub/facebookresearch_dinov2_main/dinov2/layers/swiglu_ffn.py:51: UserWarning: xFormers is not available (SwiGLU)
  warnings.warn("xFormers is not available (SwiGLU)")
/home/luketerry/.cache/torch/hub/facebookresearch_dinov2_main/dinov2/layers/swiglu_ffn.py:51: UserWarning: xFormers is not available (SwiGLU)
  warnings.warn("xFormers is not available (SwiGLU)")
/home/luketerry/.cache/torch/hub/facebookresearch_dinov2_main/dinov2/layers/swiglu_ffn.py:51: UserWarning: xFormers is not available (SwiGLU)
  warnings.warn("xFormers is not available (SwiGLU)")
/home/luketerry/.cache/torch/hub/facebookresearch_dinov2_main/dinov2/layers/swiglu_ffn.py:51: UserWarning: xFormers is not available (SwiGLU)
  warnings.warn("xFormers is not available (SwiGLU)")
/home/luketerry/.cache/torch/hub/facebookresearch_dinov2_main/dinov2/layers/attention.py:33: UserWarning: xFormers is not available (Attention)
  warnings.warn("xFormers is not available (Attention)")
/home/luketerry/.cache/torch/hub/facebookresearch_dinov2_main/dinov2/layers/attention.py:33: UserWarning: xFormers is not available (Attention)
  warnings.warn("xFormers is not available (Attention)")
/home/luketerry/.cache/torch/hub/facebookresearch_dinov2_main/dinov2/layers/attention.py:33: UserWarning: xFormers is not available (Attention)
  warnings.warn("xFormers is not available (Attention)")
/home/luketerry/.cache/torch/hub/facebookresearch_dinov2_main/dinov2/layers/block.py:40: UserWarning: xFormers is not available (Block)
  warnings.warn("xFormers is not available (Block)")
/home/luketerry/.cache/torch/hub/facebookresearch_dinov2_main/dinov2/layers/block.py:40: UserWarning: xFormers is not available (Block)
  warnings.warn("xFormers is not available (Block)")
/home/luketerry/.cache/torch/hub/facebookresearch_dinov2_main/dinov2/layers/block.py:40: UserWarning: xFormers is not available (Block)
  warnings.warn("xFormers is not available (Block)")
/home/luketerry/.cache/torch/hub/facebookresearch_dinov2_main/dinov2/layers/attention.py:33: UserWarning: xFormers is not available (Attention)
  warnings.warn("xFormers is not available (Attention)")
/home/luketerry/.cache/torch/hub/facebookresearch_dinov2_main/dinov2/layers/swiglu_ffn.py:51: UserWarning: xFormers is not available (SwiGLU)
  warnings.warn("xFormers is not available (SwiGLU)")
/home/luketerry/.cache/torch/hub/facebookresearch_dinov2_main/dinov2/layers/attention.py:33: UserWarning: xFormers is not available (Attention)
  warnings.warn("xFormers is not available (Attention)")
/home/luketerry/.cache/torch/hub/facebookresearch_dinov2_main/dinov2/layers/block.py:40: UserWarning: xFormers is not available (Block)
  warnings.warn("xFormers is not available (Block)")
/home/luketerry/.cache/torch/hub/facebookresearch_dinov2_main/dinov2/layers/block.py:40: UserWarning: xFormers is not available (Block)
  warnings.warn("xFormers is not available (Block)")
/home/luketerry/.cache/torch/hub/facebookresearch_dinov2_main/dinov2/layers/swiglu_ffn.py:51: UserWarning: xFormers is not available (SwiGLU)
  warnings.warn("xFormers is not available (SwiGLU)")
/home/luketerry/.cache/torch/hub/facebookresearch_dinov2_main/dinov2/layers/swiglu_ffn.py:51: UserWarning: xFormers is not available (SwiGLU)
  warnings.warn("xFormers is not available (SwiGLU)")
/home/luketerry/.cache/torch/hub/facebookresearch_dinov2_main/dinov2/layers/attention.py:33: UserWarning: xFormers is not available (Attention)
  warnings.warn("xFormers is not available (Attention)")
/home/luketerry/.cache/torch/hub/facebookresearch_dinov2_main/dinov2/layers/attention.py:33: UserWarning: xFormers is not available (Attention)
  warnings.warn("xFormers is not available (Attention)")
/home/luketerry/.cache/torch/hub/facebookresearch_dinov2_main/dinov2/layers/block.py:40: UserWarning: xFormers is not available (Block)
  warnings.warn("xFormers is not available (Block)")
/home/luketerry/.cache/torch/hub/facebookresearch_dinov2_main/dinov2/layers/block.py:40: UserWarning: xFormers is not available (Block)
  warnings.warn("xFormers is not available (Block)")
/home/luketerry/.cache/torch/hub/facebookresearch_dinov2_main/dinov2/layers/swiglu_ffn.py:51: UserWarning: xFormers is not available (SwiGLU)
  warnings.warn("xFormers is not available (SwiGLU)")
/home/luketerry/.cache/torch/hub/facebookresearch_dinov2_main/dinov2/layers/attention.py:33: UserWarning: xFormers is not available (Attention)
  warnings.warn("xFormers is not available (Attention)")
/home/luketerry/.cache/torch/hub/facebookresearch_dinov2_main/dinov2/layers/block.py:40: UserWarning: xFormers is not available (Block)
  warnings.warn("xFormers is not available (Block)")
Process Process-4:
Traceback (most recent call last):
  File "/home/jroth/.conda/envs/mct/lib/python3.10/multiprocessing/process.py", line 314, in _bootstrap
    self.run()
  File "/home/jroth/.conda/envs/mct/lib/python3.10/multiprocessing/process.py", line 108, in run
    self._target(*self._args, **self._kwargs)
  File "/home/luketerry/distributed_dino_embedding/distributed_process.py", line 69, in init_process
    fn(rank, size, dataloader, embedding_dir)
  File "/home/luketerry/distributed_dino_embedding/distributed_process.py", line 28, in run
    os.makedirs(path)
  File "/home/jroth/.conda/envs/mct/lib/python3.10/os.py", line 225, in makedirs
    mkdir(name, mode)
FileExistsError: [Errno 17] File exists: '/ourdisk/hpc/ai2es/luketerry/embeddings/20230727/'
Process Process-2:
Traceback (most recent call last):
  File "/home/jroth/.conda/envs/mct/lib/python3.10/multiprocessing/process.py", line 314, in _bootstrap
    self.run()
  File "/home/jroth/.conda/envs/mct/lib/python3.10/multiprocessing/process.py", line 108, in run
    self._target(*self._args, **self._kwargs)
  File "/home/luketerry/distributed_dino_embedding/distributed_process.py", line 69, in init_process
    fn(rank, size, dataloader, embedding_dir)
  File "/home/luketerry/distributed_dino_embedding/distributed_process.py", line 28, in run
    os.makedirs(path)
  File "/home/jroth/.conda/envs/mct/lib/python3.10/os.py", line 225, in makedirs
    mkdir(name, mode)
FileExistsError: [Errno 17] File exists: '/ourdisk/hpc/ai2es/luketerry/embeddings/20220909/'
Process Process-3:
Traceback (most recent call last):
  File "/home/jroth/.conda/envs/mct/lib/python3.10/multiprocessing/process.py", line 314, in _bootstrap
    self.run()
  File "/home/jroth/.conda/envs/mct/lib/python3.10/multiprocessing/process.py", line 108, in run
    self._target(*self._args, **self._kwargs)
  File "/home/luketerry/distributed_dino_embedding/distributed_process.py", line 69, in init_process
    fn(rank, size, dataloader, embedding_dir)
  File "/home/luketerry/distributed_dino_embedding/distributed_process.py", line 20, in run
    for image, file in iter(dataloader):
  File "/home/jroth/.conda/envs/mct/lib/python3.10/site-packages/torch/utils/data/dataloader.py", line 630, in __next__
    data = self._next_data()
  File "/home/jroth/.conda/envs/mct/lib/python3.10/site-packages/torch/utils/data/dataloader.py", line 674, in _next_data
    data = self._dataset_fetcher.fetch(index)  # may raise StopIteration
  File "/home/jroth/.conda/envs/mct/lib/python3.10/site-packages/torch/utils/data/_utils/fetch.py", line 51, in fetch
    data = [self.dataset[idx] for idx in possibly_batched_index]
  File "/home/jroth/.conda/envs/mct/lib/python3.10/site-packages/torch/utils/data/_utils/fetch.py", line 51, in <listcomp>
    data = [self.dataset[idx] for idx in possibly_batched_index]
  File "/home/luketerry/distributed_dino_embedding/street_image_dataset.py", line 36, in __getitem__
    file = root + '/' + pics[idx]
IndexError: list index out of range
Process Process-3:
Traceback (most recent call last):
  File "/home/jroth/.conda/envs/mct/lib/python3.10/multiprocessing/process.py", line 314, in _bootstrap
    self.run()
  File "/home/jroth/.conda/envs/mct/lib/python3.10/multiprocessing/process.py", line 108, in run
    self._target(*self._args, **self._kwargs)
  File "/home/luketerry/distributed_dino_embedding/distributed_process.py", line 69, in init_process
    fn(rank, size, dataloader, embedding_dir)
  File "/home/luketerry/distributed_dino_embedding/distributed_process.py", line 20, in run
    for image, file in iter(dataloader):
  File "/home/jroth/.conda/envs/mct/lib/python3.10/site-packages/torch/utils/data/dataloader.py", line 630, in __next__
    data = self._next_data()
  File "/home/jroth/.conda/envs/mct/lib/python3.10/site-packages/torch/utils/data/dataloader.py", line 674, in _next_data
    data = self._dataset_fetcher.fetch(index)  # may raise StopIteration
  File "/home/jroth/.conda/envs/mct/lib/python3.10/site-packages/torch/utils/data/_utils/fetch.py", line 51, in fetch
    data = [self.dataset[idx] for idx in possibly_batched_index]
  File "/home/jroth/.conda/envs/mct/lib/python3.10/site-packages/torch/utils/data/_utils/fetch.py", line 51, in <listcomp>
    data = [self.dataset[idx] for idx in possibly_batched_index]
  File "/home/luketerry/distributed_dino_embedding/street_image_dataset.py", line 36, in __getitem__
    file = root + '/' + pics[idx]
IndexError: list index out of range
Process Process-3:
Traceback (most recent call last):
  File "/home/jroth/.conda/envs/mct/lib/python3.10/multiprocessing/process.py", line 314, in _bootstrap
    self.run()
  File "/home/jroth/.conda/envs/mct/lib/python3.10/multiprocessing/process.py", line 108, in run
    self._target(*self._args, **self._kwargs)
  File "/home/luketerry/distributed_dino_embedding/distributed_process.py", line 69, in init_process
    fn(rank, size, dataloader, embedding_dir)
  File "/home/luketerry/distributed_dino_embedding/distributed_process.py", line 20, in run
    for image, file in iter(dataloader):
  File "/home/jroth/.conda/envs/mct/lib/python3.10/site-packages/torch/utils/data/dataloader.py", line 630, in __next__
    data = self._next_data()
  File "/home/jroth/.conda/envs/mct/lib/python3.10/site-packages/torch/utils/data/dataloader.py", line 674, in _next_data
    data = self._dataset_fetcher.fetch(index)  # may raise StopIteration
  File "/home/jroth/.conda/envs/mct/lib/python3.10/site-packages/torch/utils/data/_utils/fetch.py", line 51, in fetch
    data = [self.dataset[idx] for idx in possibly_batched_index]
  File "/home/jroth/.conda/envs/mct/lib/python3.10/site-packages/torch/utils/data/_utils/fetch.py", line 51, in <listcomp>
    data = [self.dataset[idx] for idx in possibly_batched_index]
  File "/home/luketerry/distributed_dino_embedding/street_image_dataset.py", line 36, in __getitem__
    file = root + '/' + pics[idx]
IndexError: list index out of range
Process Process-3:
Traceback (most recent call last):
  File "/home/jroth/.conda/envs/mct/lib/python3.10/multiprocessing/process.py", line 314, in _bootstrap
    self.run()
  File "/home/jroth/.conda/envs/mct/lib/python3.10/multiprocessing/process.py", line 108, in run
    self._target(*self._args, **self._kwargs)
  File "/home/luketerry/distributed_dino_embedding/distributed_process.py", line 69, in init_process
    fn(rank, size, dataloader, embedding_dir)
  File "/home/luketerry/distributed_dino_embedding/distributed_process.py", line 20, in run
    for image, file in iter(dataloader):
  File "/home/jroth/.conda/envs/mct/lib/python3.10/site-packages/torch/utils/data/dataloader.py", line 630, in __next__
    data = self._next_data()
  File "/home/jroth/.conda/envs/mct/lib/python3.10/site-packages/torch/utils/data/dataloader.py", line 674, in _next_data
    data = self._dataset_fetcher.fetch(index)  # may raise StopIteration
  File "/home/jroth/.conda/envs/mct/lib/python3.10/site-packages/torch/utils/data/_utils/fetch.py", line 51, in fetch
    data = [self.dataset[idx] for idx in possibly_batched_index]
  File "/home/jroth/.conda/envs/mct/lib/python3.10/site-packages/torch/utils/data/_utils/fetch.py", line 51, in <listcomp>
    data = [self.dataset[idx] for idx in possibly_batched_index]
  File "/home/luketerry/distributed_dino_embedding/street_image_dataset.py", line 36, in __getitem__
    file = root + '/' + pics[idx]
IndexError: list index out of range
Process Process-2:
Traceback (most recent call last):
  File "/home/jroth/.conda/envs/mct/lib/python3.10/multiprocessing/process.py", line 314, in _bootstrap
    self.run()
  File "/home/jroth/.conda/envs/mct/lib/python3.10/multiprocessing/process.py", line 108, in run
    self._target(*self._args, **self._kwargs)
  File "/home/luketerry/distributed_dino_embedding/distributed_process.py", line 69, in init_process
    fn(rank, size, dataloader, embedding_dir)
  File "/home/luketerry/distributed_dino_embedding/distributed_process.py", line 28, in run
    os.makedirs(path)
  File "/home/jroth/.conda/envs/mct/lib/python3.10/os.py", line 225, in makedirs
    mkdir(name, mode)
FileExistsError: [Errno 17] File exists: '/ourdisk/hpc/ai2es/luketerry/embeddings/20220125/'
Process Process-1:
Traceback (most recent call last):
  File "/home/jroth/.conda/envs/mct/lib/python3.10/multiprocessing/process.py", line 314, in _bootstrap
    self.run()
  File "/home/jroth/.conda/envs/mct/lib/python3.10/multiprocessing/process.py", line 108, in run
    self._target(*self._args, **self._kwargs)
  File "/home/luketerry/distributed_dino_embedding/distributed_process.py", line 69, in init_process
    fn(rank, size, dataloader, embedding_dir)
  File "/home/luketerry/distributed_dino_embedding/distributed_process.py", line 20, in run
    for image, file in iter(dataloader):
  File "/home/jroth/.conda/envs/mct/lib/python3.10/site-packages/torch/utils/data/dataloader.py", line 630, in __next__
    data = self._next_data()
  File "/home/jroth/.conda/envs/mct/lib/python3.10/site-packages/torch/utils/data/dataloader.py", line 674, in _next_data
    data = self._dataset_fetcher.fetch(index)  # may raise StopIteration
  File "/home/jroth/.conda/envs/mct/lib/python3.10/site-packages/torch/utils/data/_utils/fetch.py", line 51, in fetch
    data = [self.dataset[idx] for idx in possibly_batched_index]
  File "/home/jroth/.conda/envs/mct/lib/python3.10/site-packages/torch/utils/data/_utils/fetch.py", line 51, in <listcomp>
    data = [self.dataset[idx] for idx in possibly_batched_index]
  File "/home/luketerry/distributed_dino_embedding/street_image_dataset.py", line 36, in __getitem__
    file = root + '/' + pics[idx]
IndexError: list index out of range
Process Process-2:
Traceback (most recent call last):
  File "/home/jroth/.conda/envs/mct/lib/python3.10/multiprocessing/process.py", line 314, in _bootstrap
    self.run()
  File "/home/jroth/.conda/envs/mct/lib/python3.10/multiprocessing/process.py", line 108, in run
    self._target(*self._args, **self._kwargs)
  File "/home/luketerry/distributed_dino_embedding/distributed_process.py", line 69, in init_process
    fn(rank, size, dataloader, embedding_dir)
  File "/home/luketerry/distributed_dino_embedding/distributed_process.py", line 20, in run
    for image, file in iter(dataloader):
  File "/home/jroth/.conda/envs/mct/lib/python3.10/site-packages/torch/utils/data/dataloader.py", line 630, in __next__
    data = self._next_data()
  File "/home/jroth/.conda/envs/mct/lib/python3.10/site-packages/torch/utils/data/dataloader.py", line 674, in _next_data
    data = self._dataset_fetcher.fetch(index)  # may raise StopIteration
  File "/home/jroth/.conda/envs/mct/lib/python3.10/site-packages/torch/utils/data/_utils/fetch.py", line 51, in fetch
    data = [self.dataset[idx] for idx in possibly_batched_index]
  File "/home/jroth/.conda/envs/mct/lib/python3.10/site-packages/torch/utils/data/_utils/fetch.py", line 51, in <listcomp>
    data = [self.dataset[idx] for idx in possibly_batched_index]
  File "/home/luketerry/distributed_dino_embedding/street_image_dataset.py", line 36, in __getitem__
    file = root + '/' + pics[idx]
IndexError: list index out of range
Process Process-2:
Traceback (most recent call last):
  File "/home/jroth/.conda/envs/mct/lib/python3.10/multiprocessing/process.py", line 314, in _bootstrap
    self.run()
  File "/home/jroth/.conda/envs/mct/lib/python3.10/multiprocessing/process.py", line 108, in run
    self._target(*self._args, **self._kwargs)
  File "/home/luketerry/distributed_dino_embedding/distributed_process.py", line 69, in init_process
    fn(rank, size, dataloader, embedding_dir)
  File "/home/luketerry/distributed_dino_embedding/distributed_process.py", line 20, in run
    for image, file in iter(dataloader):
  File "/home/jroth/.conda/envs/mct/lib/python3.10/site-packages/torch/utils/data/dataloader.py", line 630, in __next__
    data = self._next_data()
  File "/home/jroth/.conda/envs/mct/lib/python3.10/site-packages/torch/utils/data/dataloader.py", line 674, in _next_data
    data = self._dataset_fetcher.fetch(index)  # may raise StopIteration
  File "/home/jroth/.conda/envs/mct/lib/python3.10/site-packages/torch/utils/data/_utils/fetch.py", line 51, in fetch
    data = [self.dataset[idx] for idx in possibly_batched_index]
  File "/home/jroth/.conda/envs/mct/lib/python3.10/site-packages/torch/utils/data/_utils/fetch.py", line 51, in <listcomp>
    data = [self.dataset[idx] for idx in possibly_batched_index]
  File "/home/luketerry/distributed_dino_embedding/street_image_dataset.py", line 36, in __getitem__
    file = root + '/' + pics[idx]
IndexError: list index out of range
Process Process-4:
Traceback (most recent call last):
  File "/home/jroth/.conda/envs/mct/lib/python3.10/multiprocessing/process.py", line 314, in _bootstrap
    self.run()
  File "/home/jroth/.conda/envs/mct/lib/python3.10/multiprocessing/process.py", line 108, in run
    self._target(*self._args, **self._kwargs)
  File "/home/luketerry/distributed_dino_embedding/distributed_process.py", line 69, in init_process
    fn(rank, size, dataloader, embedding_dir)
  File "/home/luketerry/distributed_dino_embedding/distributed_process.py", line 20, in run
    for image, file in iter(dataloader):
  File "/home/jroth/.conda/envs/mct/lib/python3.10/site-packages/torch/utils/data/dataloader.py", line 630, in __next__
    data = self._next_data()
  File "/home/jroth/.conda/envs/mct/lib/python3.10/site-packages/torch/utils/data/dataloader.py", line 674, in _next_data
    data = self._dataset_fetcher.fetch(index)  # may raise StopIteration
  File "/home/jroth/.conda/envs/mct/lib/python3.10/site-packages/torch/utils/data/_utils/fetch.py", line 51, in fetch
    data = [self.dataset[idx] for idx in possibly_batched_index]
  File "/home/jroth/.conda/envs/mct/lib/python3.10/site-packages/torch/utils/data/_utils/fetch.py", line 51, in <listcomp>
    data = [self.dataset[idx] for idx in possibly_batched_index]
  File "/home/luketerry/distributed_dino_embedding/street_image_dataset.py", line 36, in __getitem__
    file = root + '/' + pics[idx]
IndexError: list index out of range
Process Process-4:
Traceback (most recent call last):
  File "/home/jroth/.conda/envs/mct/lib/python3.10/multiprocessing/process.py", line 314, in _bootstrap
    self.run()
  File "/home/jroth/.conda/envs/mct/lib/python3.10/multiprocessing/process.py", line 108, in run
    self._target(*self._args, **self._kwargs)
  File "/home/luketerry/distributed_dino_embedding/distributed_process.py", line 69, in init_process
    fn(rank, size, dataloader, embedding_dir)
  File "/home/luketerry/distributed_dino_embedding/distributed_process.py", line 20, in run
    for image, file in iter(dataloader):
  File "/home/jroth/.conda/envs/mct/lib/python3.10/site-packages/torch/utils/data/dataloader.py", line 630, in __next__
    data = self._next_data()
  File "/home/jroth/.conda/envs/mct/lib/python3.10/site-packages/torch/utils/data/dataloader.py", line 674, in _next_data
    data = self._dataset_fetcher.fetch(index)  # may raise StopIteration
  File "/home/jroth/.conda/envs/mct/lib/python3.10/site-packages/torch/utils/data/_utils/fetch.py", line 51, in fetch
    data = [self.dataset[idx] for idx in possibly_batched_index]
  File "/home/jroth/.conda/envs/mct/lib/python3.10/site-packages/torch/utils/data/_utils/fetch.py", line 51, in <listcomp>
    data = [self.dataset[idx] for idx in possibly_batched_index]
  File "/home/luketerry/distributed_dino_embedding/street_image_dataset.py", line 36, in __getitem__
    file = root + '/' + pics[idx]
IndexError: list index out of range
Process Process-4:
Traceback (most recent call last):
  File "/home/jroth/.conda/envs/mct/lib/python3.10/multiprocessing/process.py", line 314, in _bootstrap
    self.run()
  File "/home/jroth/.conda/envs/mct/lib/python3.10/multiprocessing/process.py", line 108, in run
    self._target(*self._args, **self._kwargs)
  File "/home/luketerry/distributed_dino_embedding/distributed_process.py", line 69, in init_process
    fn(rank, size, dataloader, embedding_dir)
  File "/home/luketerry/distributed_dino_embedding/distributed_process.py", line 20, in run
    for image, file in iter(dataloader):
  File "/home/jroth/.conda/envs/mct/lib/python3.10/site-packages/torch/utils/data/dataloader.py", line 630, in __next__
    data = self._next_data()
  File "/home/jroth/.conda/envs/mct/lib/python3.10/site-packages/torch/utils/data/dataloader.py", line 674, in _next_data
    data = self._dataset_fetcher.fetch(index)  # may raise StopIteration
  File "/home/jroth/.conda/envs/mct/lib/python3.10/site-packages/torch/utils/data/_utils/fetch.py", line 51, in fetch
    data = [self.dataset[idx] for idx in possibly_batched_index]
  File "/home/jroth/.conda/envs/mct/lib/python3.10/site-packages/torch/utils/data/_utils/fetch.py", line 51, in <listcomp>
    data = [self.dataset[idx] for idx in possibly_batched_index]
  File "/home/luketerry/distributed_dino_embedding/street_image_dataset.py", line 36, in __getitem__
    file = root + '/' + pics[idx]
IndexError: list index out of range
